Workbook

Sheet About
A1: A/R tracker — 90+ outstanding extract (de-identified)
A3: This sample is 90+ only: one row per patient account on a 23 Sep 2026 90+ outstanding extract, not one row per open charge, and not the full open A/R board. Do not compare this file's mix to the case-study story (31.4% to 18.7% of all open A/R). Placeholder IDs only (RP-100x / P-20xx), not PMS IDs. No real names. Most recent visit and next appointment are demo fields; next appointment uses TODAY()+n so dates stay after today. Some responsible parties cover 2-3 patients.
A10: Snapshot | B10: 46288
A11: Rows (patient accounts) | B11: 110
A12: Grain | B12: One row per patient account on the 90+ extract (not per charge)
A13: See | B13: Ledger · Calcs · Aging pivot (tables + pie)

Sheet Ledger
A1: Responsible Party Patient ID | B1: Patient ID | C1: Most recent visit | D1: Next appointment | E1: Total owing | F1: Patient total owing | G1: Insurance total owing | H1: Patient 0–30 | I1: Patient 31–60 | J1: Patient 61–90 | K1: Patient over 90 | L1: Insurance 0–30 | M1: Insurance 31–60 | N1: Insurance 61–90 | O1: Insurance over 90 | P1: Primary bucket | Q1: Has next appointment | R1: Days since last visit
A2: RP-1001 | B2: P-2001 | C2: 46101 | E2: 6.4 | F2: 6.4 | G2: 0 | H2: 0 | I2: 0 | J2: 0 | K2: 6.4 | L2: 0 | M2: 0 | N2: 0 | O2: 0 | P2: 90+ | Q2: No | R2: =DATE(2026,9,23)-C2
A3: RP-1002 | B3: P-2002 | C3: 45941 | D3: =TODAY()+54 | E3: 53.4 | F3: 53.4 | G3: 0 | H3: 0 | I3: 0 | J3: 0 | K3: 53.4 | L3: 0 | M3: 0 | N3: 0 | O3: 0 | P3: 90+ | Q3: Yes | R3: =DATE(2026,9,23)-C3
A4: RP-1003 | B4: P-2003 | C4: 46131 | E4: 36 | F4: 36 | G4: 0 | H4: 0 | I4: 0 | J4: 0 | K4: 36 | L4: 0 | M4: 0 | N4: 0 | O4: 0 | P4: 90+ | Q4: No | R4: =DATE(2026,9,23)-C4
A5: RP-1003 | B5: P-2004 | C5: 46020 | E5: 18.3 | F5: 18.3 | G5: 0 | H5: 0 | I5: 0 | J5: 0 | K5: 18.3 | L5: 0 | M5: 0 | N5: 0 | O5: 0 | P5: 90+ | Q5: No | R5: =DATE(2026,9,23)-C5
A6: RP-1003 | B6: P-2005 | C6: 45890 | E6: 95 | F6: 95 | G6: 0 | H6: 0 | I6: 0 | J6: 0 | K6: 95 | L6: 0 | M6: 0 | N6: 0 | O6: 0 | P6: 90+ | Q6: No | R6: =DATE(2026,9,23)-C6
A7: RP-1004 | B7: P-2006 | C7: 45937 | E7: 30 | F7: 30 | G7: 0 | H7: 0 | I7: 0 | J7: 0 | K7: 30 | L7: 0 | M7: 0 | N7: 0 | O7: 0 | P7: 90+ | Q7: No | R7: =DATE(2026,9,23)-C7
A8: RP-1005 | B8: P-2007 | C8: 45961 | D8: =TODAY()+29 | E8: 95 | F8: 95 | G8: 0 | H8: 0 | I8: 0 | J8: 0 | K8: 95 | L8: 0 | M8: 0 | N8: 0 | O8: 0 | P8: 90+ | Q8: Yes | R8: =DATE(2026,9,23)-C8
A9: RP-1006 | B9: P-2008 | C9: 46021 | E9: 42.5 | F9: 42.5 | G9: 0 | H9: 0 | I9: 0 | J9: 0 | K9: 42.5 | L9: 0 | M9: 0 | N9: 0 | O9: 0 | P9: 90+ | Q9: No | R9: =DATE(2026,9,23)-C9
A10: RP-1006 | B10: P-2009 | C10: 45978 | E10: 11 | F10: 11 | G10: 0 | H10: 0 | I10: 0 | J10: 0 | K10: 11 | L10: 0 | M10: 0 | N10: 0 | O10: 0 | P10: 90+ | Q10: No | R10: =DATE(2026,9,23)-C10
A11: RP-1007 | B11: P-2010 | C11: 46097 | E11: 303 | F11: 303 | G11: 0 | H11: 0 | I11: 0 | J11: 0 | K11: 303 | L11: 0 | M11: 0 | N11: 0 | O11: 0 | P11: 90+ | Q11: No | R11: =DATE(2026,9,23)-C11
A12: RP-1004 | B12: P-2006 | C12: 45937 | E12: 24 | F12: 24 | G12: 0 | H12: 0 | I12: 0 | J12: 0 | K12: 24 | L12: 0 | M12: 0 | N12: 0 | O12: 0 | P12: 90+ | Q12: No | R12: =DATE(2026,9,23)-C12
A13: RP-1007 | B13: P-2011 | C13: 46122 | E13: 137.5 | F13: 137.5 | G13: 0 | H13: 0 | I13: 0 | J13: 0 | K13: 137.5 | L13: 0 | M13: 0 | N13: 0 | O13: 0 | P13: 90+ | Q13: No | R13: =DATE(2026,9,23)-C13
A14: RP-1008 | B14: P-2012 | C14: 45917 | E14: 40 | F14: 40 | G14: 0 | H14: 0 | I14: 0 | J14: 0 | K14: 40 | L14: 0 | M14: 0 | N14: 0 | O14: 0 | P14: 90+ | Q14: No | R14: =DATE(2026,9,23)-C14
A15: RP-1003 | B15: P-2003 | C15: 46131 | E15: 15 | F15: 15 | G15: 0 | H15: 0 | I15: 0 | J15: 0 | K15: 15 | L15: 0 | M15: 0 | N15: 0 | O15: 0 | P15: 90+ | Q15: No | R15: =DATE(2026,9,23)-C15
A16: RP-1009 | B16: P-2013 | C16: 46152 | E16: 39.6 | F16: 39.6 | G16: 0 | H16: 0 | I16: 0 | J16: 0 | K16: 39.6 | L16: 0 | M16: 0 | N16: 0 | O16: 0 | P16: 90+ | Q16: No | R16: =DATE(2026,9,23)-C16
A17: RP-1009 | B17: P-2014 | C17: 45950 | E17: 61 | F17: 61 | G17: 0 | H17: 0 | I17: 0 | J17: 0 | K17: 61 | L17: 0 | M17: 0 | N17: 0 | O17: 0 | P17: 90+ | Q17: No | R17: =DATE(2026,9,23)-C17
A18: RP-1009 | B18: P-2015 | C18: 46022 | D18: =TODAY()+29 | E18: 40.05 | F18: 40.05 | G18: 0 | H18: 0 | I18: 0 | J18: 0 | K18: 40.05 | L18: 0 | M18: 0 | N18: 0 | O18: 0 | P18: 90+ | Q18: Yes | R18: =DATE(2026,9,23)-C18
A19: RP-1010 | B19: P-2016 | C19: 45984 | E19: 83.2 | F19: 83.2 | G19: 0 | H19: 0 | I19: 0 | J19: 0 | K19: 83.2 | L19: 0 | M19: 0 | N19: 0 | O19: 0 | P19: 90+ | Q19: No | R19: =DATE(2026,9,23)-C19
A20: RP-1010 | B20: P-2017 | C20: 45942 | D20: =TODAY()+23 | E20: 30 | F20: 30 | G20: 0 | H20: 0 | I20: 0 | J20: 0 | K20: 30 | L20: 0 | M20: 0 | N20: 0 | O20: 0 | P20: 90+ | Q20: Yes | R20: =DATE(2026,9,23)-C20
A21: RP-1005 | B21: P-2007 | C21: 45961 | D21: =TODAY()+29 | E21: 195 | F21: 195 | G21: 0 | H21: 0 | I21: 0 | J21: 0 | K21: 195 | L21: 0 | M21: 0 | N21: 0 | O21: 0 | P21: 90+ | Q21: Yes | R21: =DATE(2026,9,23)-C21
A22: RP-1011 | B22: P-2018 | C22: 46036 | D22: =TODAY()+20 | E22: 37 | F22: 37 | G22: 0 | H22: 0 | I22: 0 | J22: 0 | K22: 37 | L22: 0 | M22: 0 | N22: 0 | O22: 0 | P22: 90+ | Q22: Yes | R22: =DATE(2026,9,23)-C22
A23: RP-1012 | B23: P-2019 | C23: 46181 | D23: =TODAY()+59 | E23: 4 | F23: 4 | G23: 0 | H23: 0 | I23: 0 | J23: 0 | K23: 4 | L23: 0 | M23: 0 | N23: 0 | O23: 0 | P23: 90+ | Q23: Yes | R23: =DATE(2026,9,23)-C23
A24: RP-1012 | B24: P-2020 | C24: 46008 | E24: 109 | F24: 109 | G24: 0 | H24: 0 | I24: 0 | J24: 0 | K24: 109 | L24: 0 | M24: 0 | N24: 0 | O24: 0 | P24: 90+ | Q24: No | R24: =DATE(2026,9,23)-C24
A25: RP-1012 | B25: P-2021 | C25: 46158 | E25: 159.7 | F25: 159.7 | G25: 0 | H25: 0 | I25: 0 | J25: 0 | K25: 159.7 | L25: 0 | M25: 0 | N25: 0 | O25: 0 | P25: 90+ | Q25: No | R25: =DATE(2026,9,23)-C25
A26: RP-1008 | B26: P-2012 | C26: 45917 | E26: 59.6 | F26: 59.6 | G26: 0 | H26: 0 | I26: 0 | J26: 0 | K26: 59.6 | L26: 0 | M26: 0 | N26: 0 | O26: 0 | P26: 90+ | Q26: No | R26: =DATE(2026,9,23)-C26
A27: RP-1013 | B27: P-2022 | C27: 45961 | E27: 53.4 | F27: 53.4 | G27: 0 | H27: 0 | I27: 0 | J27: 0 | K27: 53.4 | L27: 0 | M27: 0 | N27: 0 | O27: 0 | P27: 90+ | Q27: No | R27: =DATE(2026,9,23)-C27
A28: RP-1014 | B28: P-2023 | C28: 46047 | D28: =TODAY()+41 | E28: 14 | F28: 14 | G28: 0 | H28: 0 | I28: 0 | J28: 0 | K28: 14 | L28: 0 | M28: 0 | N28: 0 | O28: 0 | P28: 90+ | Q28: Yes | R28: =DATE(2026,9,23)-C28
A29: RP-1015 | B29: P-2024 | C29: 46079 | D29: =TODAY()+10 | E29: 1431.34 | F29: 1431.34 | G29: 0 | H29: 0 | I29: 0 | J29: 0 | K29: 1431.34 | L29: 0 | M29: 0 | N29: 0 | O29: 0 | P29: 90+ | Q29: Yes | R29: =DATE(2026,9,23)-C29
A30: RP-1009 | B30: P-2013 | C30: 46152 | E30: 109.6 | F30: 109.6 | G30: 0 | H30: 0 | I30: 0 | J30: 0 | K30: 109.6 | L30: 0 | M30: 0 | N30: 0 | O30: 0 | P30: 90+ | Q30: No | R30: =DATE(2026,9,23)-C30
A31: RP-1015 | B31: P-2025 | C31: 45945 | E31: 30 | F31: 30 | G31: 0 | H31: 0 | I31: 0 | J31: 0 | K31: 30 | L31: 0 | M31: 0 | N31: 0 | O31: 0 | P31: 90+ | Q31: No | R31: =DATE(2026,9,23)-C31
A32: RP-1016 | B32: P-2026 | C32: 46065 | D32: =TODAY()+24 | E32: 2 | F32: 2 | G32: 0 | H32: 0 | I32: 0 | J32: 0 | K32: 2 | L32: 0 | M32: 0 | N32: 0 | O32: 0 | P32: 90+ | Q32: Yes | R32: =DATE(2026,9,23)-C32
A33: RP-1017 | B33: P-2027 | C33: 46170 | E33: 23 | F33: 23 | G33: 0 | H33: 0 | I33: 0 | J33: 0 | K33: 23 | L33: 0 | M33: 0 | N33: 0 | O33: 0 | P33: 90+ | Q33: No | R33: =DATE(2026,9,23)-C33
A34: RP-1017 | B34: P-2028 | C34: 45931 | E34: 16 | F34: 16 | G34: 0 | H34: 0 | I34: 0 | J34: 0 | K34: 16 | L34: 0 | M34: 0 | N34: 0 | O34: 0 | P34: 90+ | Q34: No | R34: =DATE(2026,9,23)-C34
A35: RP-1017 | B35: P-2027 | C35: 46170 | E35: 6.3 | F35: 6.3 | G35: 0 | H35: 0 | I35: 0 | J35: 0 | K35: 6.3 | L35: 0 | M35: 0 | N35: 0 | O35: 0 | P35: 90+ | Q35: No | R35: =DATE(2026,9,23)-C35
A36: RP-1005 | B36: P-2007 | C36: 45961 | D36: =TODAY()+29 | E36: 233 | F36: 233 | G36: 0 | H36: 0 | I36: 0 | J36: 0 | K36: 233 | L36: 0 | M36: 0 | N36: 0 | O36: 0 | P36: 90+ | Q36: Yes | R36: =DATE(2026,9,23)-C36
A37: RP-1017 | B37: P-2029 | C37: 46067 | E37: 103.25 | F37: 103.25 | G37: 0 | H37: 0 | I37: 0 | J37: 0 | K37: 103.25 | L37: 0 | M37: 0 | N37: 0 | O37: 0 | P37: 90+ | Q37: No | R37: =DATE(2026,9,23)-C37
A38: RP-1018 | B38: P-2030 | C38: 46048 | E38: 30 | F38: 30 | G38: 0 | H38: 0 | I38: 0 | J38: 0 | K38: 30 | L38: 0 | M38: 0 | N38: 0 | O38: 0 | P38: 90+ | Q38: No | R38: =DATE(2026,9,23)-C38
A39: RP-1018 | B39: P-2031 | C39: 45906 | D39: =TODAY()+8 | E39: 16 | F39: 16 | G39: 0 | H39: 0 | I39: 0 | J39: 0 | K39: 16 | L39: 0 | M39: 0 | N39: 0 | O39: 0 | P39: 90+ | Q39: Yes | R39: =DATE(2026,9,23)-C39
A40: RP-1019 | B40: P-2032 | C40: 46141 | E40: 2226.15 | F40: 1228.78 | G40: 997.37 | H40: 0 | I40: 0 | J40: 0 | K40: 1228.78 | L40: 0 | M40: 0 | N40: 0 | O40: 997.37 | P40: 90+ | Q40: No | R40: =DATE(2026,9,23)-C40
...

Sheet Calcs
A1: Calculation tables
A3: Headline
A4: Accounts | B4: =COUNTA(Ledger!B2:B111)
A5: Total owing | B5: =SUM(Ledger!E2:E111)
A6: Patient owing | B6: =SUM(Ledger!F2:F111)
A7: Insurance owing | B7: =SUM(Ledger!G2:G111)
A8: Patient share of open | B8: =IF(B5=0,0,B6/B5)
A9: Patient over 90 | B9: =SUM(Ledger!K2:K111)
A10: 90+ share of patient $ | B10: =IF(B6=0,0,B9/B6)
A11: 90+ accounts (patient $ > 0) | B11: =COUNTIF(Ledger!K2:K111,">0")
A12: 90+ with no next appointment | B12: =COUNTIFS(Ledger!K2:K111,">0",Ledger!Q2:Q111,"No")
A13: Unique responsible parties | B13: =SUMPRODUCT(1/COUNTIF(Ledger!A2:A111,Ledger!A2:A111))
A15: Aging mix — dollars
A16: Bucket | B16: Patient $ | C16: Insurance $ | D16: Total $ | E16: Share
A17: 0–30 | B17: =SUM(Ledger!H2:H111) | C17: =SUM(Ledger!L2:L111) | D17: =B17+C17 | E17: =IF($D$21=0,0,D17/$D$21)
A18: 31–60 | B18: =SUM(Ledger!I2:I111) | C18: =SUM(Ledger!M2:M111) | D18: =B18+C18 | E18: =IF($D$21=0,0,D18/$D$21)
A19: 61–90 | B19: =SUM(Ledger!J2:J111) | C19: =SUM(Ledger!N2:N111) | D19: =B19+C19 | E19: =IF($D$21=0,0,D19/$D$21)
A20: 90+ | B20: =SUM(Ledger!K2:K111) | C20: =SUM(Ledger!O2:O111) | D20: =B20+C20 | E20: =IF($D$21=0,0,D20/$D$21)
A21: Total | B21: =SUM(B17:B20) | C21: =SUM(C17:C20) | D21: =SUM(D17:D20) | E21: =SUM(E17:E20)
A23: Huddle flags
A24: Patient 90+ and no next appointment (work first) | B24: =B12
A25: Open $ on those accounts | B25: =SUMIFS(Ledger!E2:E111,Ledger!K2:K111,">0",Ledger!Q2:Q111,"No")

Sheet Aging pivot
A1: Pivot — aging bucket × patient vs insurance
A2: Live SUMIFS off Ledger. Change a dollar on Ledger and this sheet moves.
A4: Primary bucket | B4: Patient $ | C4: Insurance $ | D4: Accounts | E4: No next appointment
A5: 0–30 | B5: =SUMIF(Ledger!P:P,A5,Ledger!F:F) | C5: =SUMIF(Ledger!P:P,A5,Ledger!G:G) | D5: =COUNTIF(Ledger!P:P,A5) | E5: =COUNTIFS(Ledger!P:P,A5,Ledger!Q:Q,"No")
A6: 31–60 | B6: =SUMIF(Ledger!P:P,A6,Ledger!F:F) | C6: =SUMIF(Ledger!P:P,A6,Ledger!G:G) | D6: =COUNTIF(Ledger!P:P,A6) | E6: =COUNTIFS(Ledger!P:P,A6,Ledger!Q:Q,"No")
A7: 61–90 | B7: =SUMIF(Ledger!P:P,A7,Ledger!F:F) | C7: =SUMIF(Ledger!P:P,A7,Ledger!G:G) | D7: =COUNTIF(Ledger!P:P,A7) | E7: =COUNTIFS(Ledger!P:P,A7,Ledger!Q:Q,"No")
A8: 90+ | B8: =SUMIF(Ledger!P:P,A8,Ledger!F:F) | C8: =SUMIF(Ledger!P:P,A8,Ledger!G:G) | D8: =COUNTIF(Ledger!P:P,A8) | E8: =COUNTIFS(Ledger!P:P,A8,Ledger!Q:Q,"No")
A9: Total | B9: =SUM(B5:B8) | C9: =SUM(C5:C8) | D9: =SUM(D5:D8) | E9: =SUM(E5:E8)
A11: Pivot — responsible party (open $ ≥ $200)
A12: Filter this table in Excel (Data → Filter) or insert a PivotTable from ARLedger.
A13: Responsible Party Patient ID | B13: Total owing | C13: Patient $ | D13: Insurance $
A14: RP-1030 | B14: =SUMIF(Ledger!A:A,A14,Ledger!E:E) | C14: =SUMIF(Ledger!A:A,A14,Ledger!F:F) | D14: =SUMIF(Ledger!A:A,A14,Ledger!G:G)
A15: RP-1038 | B15: =SUMIF(Ledger!A:A,A15,Ledger!E:E) | C15: =SUMIF(Ledger!A:A,A15,Ledger!F:F) | D15: =SUMIF(Ledger!A:A,A15,Ledger!G:G)
A16: RP-1055 | B16: =SUMIF(Ledger!A:A,A16,Ledger!E:E) | C16: =SUMIF(Ledger!A:A,A16,Ledger!F:F) | D16: =SUMIF(Ledger!A:A,A16,Ledger!G:G)
A17: RP-1019 | B17: =SUMIF(Ledger!A:A,A17,Ledger!E:E) | C17: =SUMIF(Ledger!A:A,A17,Ledger!F:F) | D17: =SUMIF(Ledger!A:A,A17,Ledger!G:G)
A18: RP-1015 | B18: =SUMIF(Ledger!A:A,A18,Ledger!E:E) | C18: =SUMIF(Ledger!A:A,A18,Ledger!F:F) | D18: =SUMIF(Ledger!A:A,A18,Ledger!G:G)
A19: RP-1023 | B19: =SUMIF(Ledger!A:A,A19,Ledger!E:E) | C19: =SUMIF(Ledger!A:A,A19,Ledger!F:F) | D19: =SUMIF(Ledger!A:A,A19,Ledger!G:G)
A20: RP-1027 | B20: =SUMIF(Ledger!A:A,A20,Ledger!E:E) | C20: =SUMIF(Ledger!A:A,A20,Ledger!F:F) | D20: =SUMIF(Ledger!A:A,A20,Ledger!G:G)
A21: RP-1005 | B21: =SUMIF(Ledger!A:A,A21,Ledger!E:E) | C21: =SUMIF(Ledger!A:A,A21,Ledger!F:F) | D21: =SUMIF(Ledger!A:A,A21,Ledger!G:G)
A22: RP-1009 | B22: =SUMIF(Ledger!A:A,A22,Ledger!E:E) | C22: =SUMIF(Ledger!A:A,A22,Ledger!F:F) | D22: =SUMIF(Ledger!A:A,A22,Ledger!G:G)
A23: RP-1017 | B23: =SUMIF(Ledger!A:A,A23,Ledger!E:E) | C23: =SUMIF(Ledger!A:A,A23,Ledger!F:F) | D23: =SUMIF(Ledger!A:A,A23,Ledger!G:G)
A24: RP-1007 | B24: =SUMIF(Ledger!A:A,A24,Ledger!E:E) | C24: =SUMIF(Ledger!A:A,A24,Ledger!F:F) | D24: =SUMIF(Ledger!A:A,A24,Ledger!G:G)
A25: RP-1043 | B25: =SUMIF(Ledger!A:A,A25,Ledger!E:E) | C25: =SUMIF(Ledger!A:A,A25,Ledger!F:F) | D25: =SUMIF(Ledger!A:A,A25,Ledger!G:G)
... A28: RP-1012 | B28: =SUMIF(Ledger!A:A,A28,Ledger!E:E) | C28: =SUMIF(Ledger!A:A,A28,Ledger!F:F) | D28: =SUMIF(Ledger!A:A,A28,Ledger!G:G)
A30: Next appointment
A31: Status | B31: Patients | C31: Open $ | D31: Share
A32: Scheduled | B32: =COUNTIF(Ledger!Q2:Q111,"Yes") | C32: =SUMIF(Ledger!Q2:Q111,"Yes",Ledger!E2:E111) | D32: =IF($B$34=0,0,B32/$B$34)
A33: Not scheduled | B33: =COUNTIF(Ledger!Q2:Q111,"No") | C33: =SUMIF(Ledger!Q2:Q111,"No",Ledger!E2:E111) | D33: =IF($B$34=0,0,B33/$B$34)
A34: Total | B34: =SUM(B32:B33) | C34: =SUM(C32:C33) | D34: =SUM(D32:D33)
